Workbook

Sheet Input sheet
C1: Input cell | E1: Calculated cell
A3: Date of valuation | B3: Mar 31, 2025 | C3: Important: Before you run this spreadsheet, go into preferences in Excel and check under Calculation options
A4: Company name | B4: Lenovo Group Limited | C4: There should be a check against the iteration box. If there is not, you will get circular reasoning errors.
A5: Numbers from your base year below ( in consistent units)
B6: This year | C6: Last year | E6: Updated on January 2023 with updated Industry averages and risk premiums
A7: Country of incorporation | B7: Hong Kong
A8: Industry (US) | B8: Computers/Peripherals
A9: Industry (Global) | B9: Computers/Peripherals | C9: Last 10K | D9: Years since last 10K
A10: Revenues | B10: 69076.968 | C10: 56863.784 | D10: 0
A11: Operating income or EBIT | B11: 2006.902 | C11: 1990.822 | D11: 0.75
A12: Interest expense | B12: 293.595 | C12: 275.203
A13: Book value of equity | B13: 6659.917 | C13: 6081.187
A14: Book value of debt | B14: 5732.958 | C14: 3961.689
A15: Do you have R&D expenses to capitalize? | B15: Yes | C15: If you want to capitalize R&D, you have to input the numbers into the R&D worksheet.
A16: Do you have operating lease commitments? | B16: No | C16: If you lease or other contractual commitments that have not been converteed to debt already, say yes to this option and do the conversion.
A17: Cash and Marketable Securities | B17: 4728.124 | C17: 3559.831
A18: Cross holdings and other non-operating assets | B18: 1825.47 | C18: 1768.442
A19: Minority interests | B19: 1138.283 | C19: 1045.947
A20: Number of shares outstanding = | B20: 12404.659
A21: Current stock price = | B21: 11.83 | E21: Computed numbers: Here is what your company's numbers look like, relative to industry.
A22: Effective tax rate = | B22: 0.2 | E22: If you are not working in US dollars, you should add the inflation differential to the industry averages.
A23: Marginal tax rate = | B23: 0.165 | J23: Industry (US) | K23: Industry (Global) | L23: Global Distribution Stats
A24: The value drivers below (non-AI) | I24: Company | J24: Average | K24: Average | L24: 1st Quartile | M24: Median | N24: 3rd Quartile
A25: Revenue growth rate for next year | B25: 0.1 | E25: Revenue growth in the most recent year = | I25: =IF(C10>0,(B10/C10)^(1/D10)-1, "NA") | J25: =VLOOKUP(B8,'Industry Averages(US)'!A2:S95,3) | K25: =VLOOKUP(B9,'Industry Average Beta (Global)'!A2:N95,3) | L25: =VLOOKUP($B$9,'Input Stat Distributioons'!$A$3:$R$96,3,FALSE) | M25: =VLOOKUP($B$9,'Input Stat Distributioons'!$A$3:$R$96,4,FALSE) | N25: =VLOOKUP($B$9,'Input Stat Distributioons'!$A$3:$R$96,5,FALSE)
A26: Operating Margin for next year | B26: 0.029053128 | E26: Pre-tax operating margin in the most recent year = | I26: ='Valuation output'!B4 | J26: =VLOOKUP(B8,'Industry Averages(US)'!A2:AA95,4) | K26: =VLOOKUP(B9,'Industry Average Beta (Global)'!A2:N95,4) | L26: =VLOOKUP($B$9,'Input Stat Distributioons'!$A$3:$R$96,6,FALSE) | M26: =VLOOKUP($B$9,'Input Stat Distributioons'!$A$3:$R$96,7,FALSE) | N26: =VLOOKUP($B$9,'Input Stat Distributioons'!$A$3:$R$96,8,FALSE)
A27: Compounded annual revenue growth rate - years 2-5 = | B27: 0.08 | C27: Growth Lever | E27: Sales to capital ratio in most recent year = | I27: =B10/'Valuation output'!B58 | J27: =VLOOKUP(B8,'Industry Averages(US)'!A2:S95,14) | K27: =VLOOKUP(B9,'Industry Average Beta (Global)'!A2:N95,14) | L27: =VLOOKUP($B$9,'Input Stat Distributioons'!$A$3:$R$96,9,FALSE) | M27: =VLOOKUP($B$9,'Input Stat Distributioons'!$A$3:$R$96,10,FALSE) | N27: =VLOOKUP($B$9,'Input Stat Distributioons'!$A$3:$R$96,11,FALSE)
A28: Target pre-tax operating margin = | B28: 0.22484875 | C28: Profitability Lever | E28: Marginal sales to capital ratio = | I28: =IF(('Input sheet'!B10-'Input sheet'!C10)/(('Input sheet'!B13+'Input sheet'!B14-'Input sheet'!B17)-('Input sheet'!C13+'Input sheet'!C14-'Input sheet'!C17))>0,('Input sheet'!B10-'Input sheet'!C10)/(('Input sheet'!B13+'Input sheet'!B14-'Input sheet'!B17)-('Input sheet'!C13+'Input sheet'!C14-'Input sheet'!C17)),"NA")
A29: Year of convergence for margin | B29: 5 | C29: Speed of convergence level | E29: Return on invested capital in most recent year= | I29: ='Valuation output'!B7/'Valuation output'!B58 | J29: =VLOOKUP(B8,'Industry Averages(US)'!A2:S95,5) | K29: =VLOOKUP(B9,'Industry Average Beta (Global)'!A2:N95,5)
A30: Sales to capital ratio (for years 1-5) | B30: 3.6197887 | C30: Efficency of Growth Lever | E30: Standard deviation in stock prices = | J30: =VLOOKUP(B8,'Industry Averages(US)'!A2:S95,10) | K30: =VLOOKUP(B8,'Industry Average Beta (Global)'!A2:Z95,10)
A31: Sales to capital ratio (for years 6-10) | B31: 3.6197887 | E31: Cost of capital = | J31: =VLOOKUP(B8,'Industry Averages(US)'!A2:S95,13) | K31: =VLOOKUP(B8,'Industry Average Beta (Global)'!A2:Z95,13) | L31: =VLOOKUP($B$9,'Input Stat Distributioons'!$A$3:$R$96,12,FALSE) | M31: =VLOOKUP($B$9,'Input Stat Distributioons'!$A$3:$R$96,13,FALSE) | N31: =VLOOKUP($B$9,'Input Stat Distributioons'!$A$3:$R$96,14,FALSE)
A32: Market numbers
A33: Riskfree rate | B33: 0.0425 | E33: Valuation Output Feedback (for you to use to fine tune your inputs, if you want)
A34: Initial cost of capital = | B34: ='Cost of capital worksheet'!B13 | C34: Do not input. Go to cost of capital sheet. | E34: Revenues in year 10, based on your revenue growth = | J34: ='Valuation output'!L3+'Valuation output'!L14+'Valuation output'!L23
A35: Other inputs | E35: Pre-tax Operating Income in year 10, based on your operating margin = | J35: ='Valuation output'!M5+'Valuation output'!M16+'Valuation output'!M25
A36: Do you have employee options outstanding? | B36: No | E36: Return on invested capital in year 10, based on your sales/capital ratio = | J36: ='Valuation output'!L59
A37: Number of options outstanding = | B37: 0 | E37: Check the Diagnostics worksheet for more details.
A38: Average strike price = | B38: 0
A39: Average maturity = | B39: 0
A40: Standard deviation on stock price = | B40: 0
A42: Value Drivers for AI Chip business
...

Sheet Valuation output
B1: Base year | C1: 1 | D1: 2 | E1: 3 | F1: 4 | G1: 5 | H1: 6 | I1: 7 | J1: 8 | K1: 9 | L1: 10 | M1: Terminal year | N1: Terminal Value
A2: Rest Revenue growth rate | C2: ='Input sheet'!B25 | D2: ='Input sheet'!B27 | E2: =D2 | F2: =E2 | G2: =F2 | H2: =G2-((G2-$M$2)/5) | I2: =G2-((G2-$M$2)/5)*2 | J2: =G2-((G2-$M$2)/5)*3 | K2: =G2-((G2-$M$2)/5)*4 | L2: =G2-((G2-$M$2)/5)*5 | M2: =IF('Input sheet'!B78="Yes",'Input sheet'!B79,IF('Input sheet'!B75="Yes",'Input sheet'!B76,'Input sheet'!B33))
A3: Rest Revenues | B3: ='Input sheet'!B10-B14-B23 | C3: =B3*(1+C2) | D3: =C3*(1+D2) | E3: =D3*(1+E2) | F3: =E3*(1+F2) | G3: =F3*(1+G2) | H3: =G3*(1+H2) | I3: =H3*(1+I2) | J3: =I3*(1+J2) | ... M3: =L3*(1+M2)
A4: EBIT (Operating) margin | B4: =B5/B3 | C4: ='Input sheet'!B26 | D4: =IF(D1>'Input sheet'!$B$29,'Input sheet'!$B$28,'Input sheet'!$B$28-(('Input sheet'!$B$28-$C$15)/'Input sheet'!$B$29)*('Input sheet'!$B$29-D1)) | E4: =IF(E1>'Input sheet'!$B$29,'Input sheet'!$B$28,'Input sheet'!$B$28-(('Input sheet'!$B$28-$C$4)/'Input sheet'!$B$29)*('Input sheet'!$B$29-E1)) | F4: =IF(F1>'Input sheet'!$B$29,'Input sheet'!$B$28,'Input sheet'!$B$28-(('Input sheet'!$B$28-$C$4)/'Input sheet'!$B$29)*('Input sheet'!$B$29-F1)) | G4: =IF(G1>'Input sheet'!$B$29,'Input sheet'!$B$28,'Input sheet'!$B$28-(('Input sheet'!$B$28-$C$4)/'Input sheet'!$B$29)*('Input sheet'!$B$29-G1)) | H4: =IF(H1>'Input sheet'!$B$29,'Input sheet'!$B$28,'Input sheet'!$B$28-(('Input sheet'!$B$28-$C$4)/'Input sheet'!$B$29)*('Input sheet'!$B$29-H1)) | I4: =IF(I1>'Input sheet'!$B$29,'Input sheet'!$B$28,'Input sheet'!$B$28-(('Input sheet'!$B$28-$C$4)/'Input sheet'!$B$29)*('Input sheet'!$B$29-I1)) | J4: =IF(J1>'Input sheet'!$B$29,'Input sheet'!$B$28,'Input sheet'!$B$28-(('Input sheet'!$B$28-$C$4)/'Input sheet'!$B$29)*('Input sheet'!$B$29-J1)) | K4: =IF(K1>'Input sheet'!$B$29,'Input sheet'!$B$28,'Input sheet'!$B$28-(('Input sheet'!$B$28-$C$4)/'Input sheet'!$B$29)*('Input sheet'!$B$29-K1)) | L4: =IF(L1>'Input sheet'!$B$29,'Input sheet'!$B$28,'Input sheet'!$B$28-(('Input sheet'!$B$28-$C$4)/'Input sheet'!$B$29)*('Input sheet'!$B$29-L1)) | M4: =L4
A5: EBIT (Operating income) | B5: =IF('Input sheet'!B16="Yes",IF('Input sheet'!B15="Yes",'Input sheet'!B11+'Operating lease converter'!F32+'R& D converter'!D39,'Input sheet'!B11+'Operating lease converter'!F32),IF('Input sheet'!B15="Yes",'Input sheet'!B11+'R& D converter'!D39,'Input sheet'!B11))-B14*B15-B23*B24 | C5: =C4*C3 | D5: =D4*D3 | E5: =E4*E3 | F5: =F4*F3 | G5: =G4*G3 | H5: =H4*H3 | I5: =I4*I3 | J5: =J4*J3 | ... M5: =M4*M3
A6: Tax rate | B6: ='Input sheet'!B22 | C6: =B6 | D6: =C6 | E6: =D6 | F6: =E6 | G6: =F6 | H6: =G6+($M$6-$G$6)/5 | I6: =H6+($M$6-$G$6)/5 | J6: =I6+($M$6-$G$6)/5 | K6: =J6+($M$6-$G$6)/5 | L6: =K6+($M$6-$G$6)/5 | M6: =IF('Input sheet'!B70="Yes",'Input sheet'!B22,'Input sheet'!B23)
A7: EBIT(1-t) | B7: =IF(B5>0,B5*(1-B6),B5) | C7: =IF(C5>0,IF(C5<B10,C5,C5-(C5-B10)*C6),C5) | D7: =IF(D5>0,IF(D5<C10,D5,D5-(D5-C10)*D6),D5) | E7: =IF(E5>0,IF(E5<D10,E5,E5-(E5-D10)*E6),E5) | F7: =IF(F5>0,IF(F5<E10,F5,F5-(F5-E10)*F6),F5) | G7: =IF(G5>0,IF(G5<F10,G5,G5-(G5-F10)*G6),G5) | H7: =IF(H5>0,IF(H5<G10,H5,H5-(H5-G10)*H6),H5) | I7: =IF(I5>0,IF(I5<H10,I5,I5-(I5-H10)*I6),I5) | J7: =IF(J5>0,IF(J5<I10,J5,J5-(J5-I10)*J6),J5) | ... L7: =IF(L5>0,IF(L5<K10,L5,L5-(L5-K10)*L6),L5) | M7: =M5*(1-M6)
A8: - Reinvestment | C8: =IF('Input sheet'!$B$67="No",(D3-C3)/C57,IF('Input sheet'!$B$68=0,(C3-B3)/C57,IF('Input sheet'!$B$68=2,(E3-D3)/C57,IF('Input sheet'!$B$68=3,(F3-E3)/C57,(D3-C3)/C57)))) | D8: =IF('Input sheet'!$B$67="No",(E3-D3)/D57,IF('Input sheet'!$B$68=0,(D3-C3)/D57,IF('Input sheet'!$B$68=2,(F3-E3)/D57,IF('Input sheet'!$B$68=3,(G3-F3)/D57,(E3-D3)/D57)))) | E8: =IF('Input sheet'!$B$67="No",(F3-E3)/E57,IF('Input sheet'!$B$68=0,(E3-D3)/E57,IF('Input sheet'!$B$68=2,(G3-F3)/E57,IF('Input sheet'!$B$68=3,(H3-G3)/E57,(F3-E3)/E57)))) | F8: =IF('Input sheet'!$B$67="No",(G3-F3)/F57,IF('Input sheet'!$B$68=0,(F3-E3)/F57,IF('Input sheet'!$B$68=2,(H3-G3)/F57,IF('Input sheet'!$B$68=3,(I3-H3)/F57,(G3-F3)/F57)))) | G8: =IF('Input sheet'!$B$67="No",(H3-G3)/G57,IF('Input sheet'!$B$68=0,(G3-F3)/G57,IF('Input sheet'!$B$68=2,(I3-H3)/G57,IF('Input sheet'!$B$68=3,(J3-I3)/G57,(H3-G3)/G57)))) | H8: =IF('Input sheet'!$B$67="No",(I3-H3)/H57,IF('Input sheet'!$B$68=0,(H3-G3)/H57,IF('Input sheet'!$B$68=2,(J3-I3)/H57,IF('Input sheet'!$B$68=3,(K3-J3)/H57,(I3-H3)/H57)))) | I8: =IF('Input sheet'!$B$67="No",(J3-I3)/I57,IF('Input sheet'!$B$68=0,(I3-H3)/I57,IF('Input sheet'!$B$68=2,(K3-J3)/I57,IF('Input sheet'!$B$68=3,(L3-K3)/I57,(J3-I3)/I57)))) | J8: =IF('Input sheet'!$B$67="No",(K3-J3)/J57,IF('Input sheet'!$B$68=0,(J3-I3)/J57,IF('Input sheet'!$B$68=2,(L3-K3)/J57,IF('Input sheet'!$B$68=3,(M3-L3)/J57,(K3-J3)/J57)))) | K8: =IF('Input sheet'!$B$67="No",(L3-K3)/K57,IF('Input sheet'!$B$68=0,(K3-J3)/K57,IF('Input sheet'!$B$68=2,L3*L2/K57,IF('Input sheet'!$B$68=3,M3*M2/K57,(L3-K3)/K57)))) | L8: =IF('Input sheet'!$B$67="No",(M3-L3)/L57,IF('Input sheet'!$B$68=0,(L3-K3)/L57,IF('Input sheet'!$B$68=2,M3*M2/L57,IF('Input sheet'!$B$68=3,(M3*(1+M2)^2-M3*(1+M2))/L57,(M3-L3)/L57)))) | M8: =IF(M2>0,(M2/M59)*M7,0)
A9: FCFF | C9: =C7-C8 | D9: =D7-D8 | E9: =E7-E8 | F9: =F7-F8 | G9: =G7-G8 | H9: =H7-H8 | I9: =I7-I8 | J9: =J7-J8 | ... M9: =M7-M8 | N9: =M9/(M30-M2)
A10: NOL | B10: =IF('Input sheet'!B72="Yes",'Input sheet'!B73,0) | C10: =IF(C5<0,B10-C5,IF(B10>C5,B10-C5,0)) | D10: =IF(D5<0,C10-D5,IF(C10>D5,C10-D5,0)) | E10: =IF(E5<0,D10-E5,IF(D10>E5,D10-E5,0)) | F10: =IF(F5<0,E10-F5,IF(E10>F5,E10-F5,0)) | G10: =IF(G5<0,F10-G5,IF(F10>G5,F10-G5,0)) | H10: =IF(H5<0,G10-H5,IF(G10>H5,G10-H5,0)) | I10: =IF(I5<0,H10-I5,IF(H10>I5,H10-I5,0)) | J10: =IF(J5<0,I10-J5,IF(I10>J5,I10-J5,0)) | ... M10: =IF(M5<0,L10-M5,IF(L10>M5,L10-M5,0))
A12: Total Market (AI) | B12: ='Input sheet'!B44 | C12: =(G12-B12)/5+B12 | D12: =(G12-B12)/5+C12 | E12: =(G12-B12)/5+D12 | F12: =(G12-B12)/5+E12 | G12: =B12+3*(L12-B12)/5 | H12: =(L12-G12)/5+G12 | I12: =(L12-G12)/5+H12 | J12: =(L12-G12)/5+I12 | K12: =(L12-G12)/5+J12 | L12: ='Input sheet'!C44 | M12: =L12*(1+M2)
A13: Nvidia Market share (AI) | B13: ='Input sheet'!B45 | C13: =B13-($B$13-$L$13)/10 | D13: =C13-($B$13-$L$13)/10 | E13: =D13-($B$13-$L$13)/10 | F13: =E13-($B$13-$L$13)/10 | G13: =F13-($B$13-$L$13)/10 | H13: =G13-($B$13-$L$13)/10 | I13: =H13-($B$13-$L$13)/10 | J13: =I13-($B$13-$L$13)/10 | K13: =J13-($B$13-$L$13)/10 | L13: ='Input sheet'!C45 | M13: =L13
A14: Revenues from AI | B14: =B12*B13 | C14: =C12*C13 | D14: =D12*D13 | E14: =E12*E13 | F14: =F12*F13 | G14: =G12*G13 | H14: =H12*H13 | I14: =I12*I13 | ... M14: =M12*M13
A15: Operating Margin | B15: ='Input sheet'!B46 | C15: =B15 | D15: =IF(D1>'Input sheet'!$B$29,'Input sheet'!$C$46,'Input sheet'!$C$46-(('Input sheet'!$C$46-$C$15)/'Input sheet'!$B$29)*('Input sheet'!$B$29-D1)) | E15: =IF(E1>'Input sheet'!$B$29,'Input sheet'!$C$46,'Input sheet'!$C$46-(('Input sheet'!$C$46-$C$15)/'Input sheet'!$B$29)*('Input sheet'!$B$29-E1)) | F15: =IF(F1>'Input sheet'!$B$29,'Input sheet'!$C$46,'Input sheet'!$C$46-(('Input sheet'!$C$46-$C$15)/'Input sheet'!$B$29)*('Input sheet'!$B$29-F1)) | G15: =IF(G1>'Input sheet'!$B$29,'Input sheet'!$C$46,'Input sheet'!$C$46-(('Input sheet'!$C$46-$C$15)/'Input sheet'!$B$29)*('Input sheet'!$B$29-G1)) | H15: =IF(H1>'Input sheet'!$B$29,'Input sheet'!$C$46,'Input sheet'!$C$46-(('Input sheet'!$C$46-$C$15)/'Input sheet'!$B$29)*('Input sheet'!$B$29-H1)) | I15: =IF(I1>'Input sheet'!$B$29,'Input sheet'!$C$46,'Input sheet'!$C$46-(('Input sheet'!$C$46-$C$15)/'Input sheet'!$B$29)*('Input sheet'!$B$29-I1)) | J15: =IF(J1>'Input sheet'!$B$29,'Input sheet'!$C$46,'Input sheet'!$C$46-(('Input sheet'!$C$46-$C$15)/'Input sheet'!$B$29)*('Input sheet'!$B$29-J1)) | K15: =IF(K1>'Input sheet'!$B$29,'Input sheet'!$C$46,'Input sheet'!$C$46-(('Input sheet'!$C$46-$C$15)/'Input sheet'!$B$29)*('Input sheet'!$B$29-K1)) | L15: =IF(L1>'Input sheet'!$B$29,'Input sheet'!$C$46,'Input sheet'!$C$46-(('Input sheet'!$C$46-$C$15)/'Input sheet'!$B$29)*('Input sheet'!$B$29-L1)) | M15: =L15
A16: Operating Income | B16: =B14*B15 | C16: =C14*C15 | D16: =D14*D15 | E16: =E14*E15 | F16: =F14*F15 | G16: =G14*G15 | H16: =H14*H15 | I16: =I14*I15 | ... M16: =M14*M15
A17: EBIT (1-t) | B17: =B16*(1-B6) | C17: =C16*(1-C6) | D17: =D16*(1-D6) | E17: =E16*(1-E6) | F17: =F16*(1-F6) | G17: =G16*(1-G6) | H17: =H16*(1-H6) | I17: =I16*(1-I6) | ... M17: =M16*(1-M6)
A18: - Reinvestment | C18: =IF('Input sheet'!$B$67="No",(D14-C14)/C57,IF('Input sheet'!$B$68=0,(D14-B14)/C57,IF('Input sheet'!$B$68=2,(E14-D14)/C57,IF('Input sheet'!$B$68=3,(F14-E14)/C57,(D14-C14)/C57)))) | D18: =IF('Input sheet'!$B$67="No",(E14-D14)/D57,IF('Input sheet'!$B$68=0,(E14-C14)/D57,IF('Input sheet'!$B$68=2,(F14-E14)/D57,IF('Input sheet'!$B$68=3,(G14-F14)/D57,(E14-D14)/D57)))) | E18: =IF('Input sheet'!$B$67="No",(F14-E14)/E57,IF('Input sheet'!$B$68=0,(F14-D14)/E57,IF('Input sheet'!$B$68=2,(G14-F14)/E57,IF('Input sheet'!$B$68=3,(H14-G14)/E57,(F14-E14)/E57)))) | F18: =IF('Input sheet'!$B$67="No",(G14-F14)/F57,IF('Input sheet'!$B$68=0,(G14-E14)/F57,IF('Input sheet'!$B$68=2,(H14-G14)/F57,IF('Input sheet'!$B$68=3,(I14-H14)/F57,(G14-F14)/F57)))) | G18: =IF('Input sheet'!$B$67="No",(H14-G14)/G57,IF('Input sheet'!$B$68=0,(H14-F14)/G57,IF('Input sheet'!$B$68=2,(I14-H14)/G57,IF('Input sheet'!$B$68=3,(J14-I14)/G57,(H14-G14)/G57)))) | H18: =IF('Input sheet'!$B$67="No",(I14-H14)/H57,IF('Input sheet'!$B$68=0,(I14-G14)/H57,IF('Input sheet'!$B$68=2,(J14-I14)/H57,IF('Input sheet'!$B$68=3,(K14-J14)/H57,(I14-H14)/H57)))) | I18: =IF('Input sheet'!$B$67="No",(J14-I14)/I57,IF('Input sheet'!$B$68=0,(J14-H14)/I57,IF('Input sheet'!$B$68=2,(K14-J14)/I57,IF('Input sheet'!$B$68=3,(L14-K14)/I57,(J14-I14)/I57)))) | J18: =IF('Input sheet'!$B$67="No",(K14-J14)/J57,IF('Input sheet'!$B$68=0,(K14-I14)/J57,IF('Input sheet'!$B$68=2,(L14-K14)/J57,IF('Input sheet'!$B$68=3,(M14-L14)/J57,(K14-J14)/J57)))) | K18: =IF('Input sheet'!$B$67="No",(L14-K14)/K57,IF('Input sheet'!$B$68=0,(K14-J14)/K57,IF('Input sheet'!$B$68=2,L12*L2/K57,IF('Input sheet'!$B$68=3,M14*M2/K57,(L14-K14)/K57)))) | L18: =IF('Input sheet'!$B$67="No",(M14-L14)/L57,IF('Input sheet'!$B$68=0,(L14-K14)/L57,IF('Input sheet'!$B$68=2,M14*M2/L57,IF('Input sheet'!$B$68=3,(M14*(1+M2)*M2)/L57,(M14-L14)/L57)))) | M18: =IF(M2>0,(M2/M59)*M17,0)
A19: FCFF (AI) | C19: =C17-C18 | D19: =D17-D18 | E19: =E17-E18 | F19: =F17-F18 | G19: =G17-G18 | H19: =H17-H18 | I19: =I17-I18 | J19: =J17-J18 | ... M19: =M17-M18 | N19: =M19/(M30-M2)
A21: Total Market (Auto) | B21: ='Input sheet'!B50 | C21: =(G21-B21)/5+B21 | D21: =(G21-B21)/5+C21 | E21: =(G21-B21)/5+D21 | F21: =(G21-B21)/5+E21 | G21: =B21+2*(L21-B21)/3 | H21: =(L21-G21)/5+G21 | I21: =(L21-G21)/5+H21 | J21: =(L21-G21)/5+I21 | K21: =(L21-G21)/5+J21 | L21: ='Input sheet'!C50 | M21: =L21*(1+M2)
A22: Nvidia Market share (Auto) | B22: ='Input sheet'!B51 | C22: =B22-($B$22-$L$22)/10 | D22: =C22-($B$22-$L$22)/10 | E22: =D22-($B$22-$L$22)/10 | F22: =E22-($B$22-$L$22)/10 | G22: =F22-($B$22-$L$22)/10 | H22: =G22-($B$22-$L$22)/10 | I22: =H22-($B$22-$L$22)/10 | J22: =I22-($B$22-$L$22)/10 | K22: =J22-($B$22-$L$22)/10 | L22: ='Input sheet'!C51 | M22: =L22
A23: Revenues from Auto | B23: =B21*B22 | C23: =C21*C22 | D23: =D21*D22 | E23: =E21*E22 | F23: =F21*F22 | G23: =G21*G22 | H23: =H21*H22 | I23: =I21*I22 | ... M23: =M21*M22
A24: Operating Margin | B24: ='Input sheet'!B52 | C24: ='Input sheet'!B26 | D24: =IF(D1>'Input sheet'!$B$29,'Input sheet'!$C$52,'Input sheet'!$C$52-(('Input sheet'!$C$52-$C$24)/'Input sheet'!$B$29)*('Input sheet'!$B$29-D1)) | E24: =IF(E1>'Input sheet'!$B$29,'Input sheet'!$C$52,'Input sheet'!$C$52-(('Input sheet'!$C$52-$C$24)/'Input sheet'!$B$29)*('Input sheet'!$B$29-E1)) | F24: =IF(F1>'Input sheet'!$B$29,'Input sheet'!$C$52,'Input sheet'!$C$52-(('Input sheet'!$C$52-$C$24)/'Input sheet'!$B$29)*('Input sheet'!$B$29-F1)) | G24: =IF(G1>'Input sheet'!$B$29,'Input sheet'!$C$52,'Input sheet'!$C$52-(('Input sheet'!$C$52-$C$24)/'Input sheet'!$B$29)*('Input sheet'!$B$29-G1)) | H24: =IF(H1>'Input sheet'!$B$29,'Input sheet'!$C$52,'Input sheet'!$C$52-(('Input sheet'!$C$52-$C$24)/'Input sheet'!$B$29)*('Input sheet'!$B$29-H1)) | I24: =IF(I1>'Input sheet'!$B$29,'Input sheet'!$C$52,'Input sheet'!$C$52-(('Input sheet'!$C$52-$C$24)/'Input sheet'!$B$29)*('Input sheet'!$B$29-I1)) | J24: =IF(J1>'Input sheet'!$B$29,'Input sheet'!$C$52,'Input sheet'!$C$52-(('Input sheet'!$C$52-$C$24)/'Input sheet'!$B$29)*('Input sheet'!$B$29-J1)) | K24: =IF(K1>'Input sheet'!$B$29,'Input sheet'!$C$52,'Input sheet'!$C$52-(('Input sheet'!$C$52-$C$24)/'Input sheet'!$B$29)*('Input sheet'!$B$29-K1)) | L24: =IF(L1>'Input sheet'!$B$29,'Input sheet'!$C$52,'Input sheet'!$C$52-(('Input sheet'!$C$52-$C$24)/'Input sheet'!$B$29)*('Input sheet'!$B$29-L1)) | M24: =L24
A25: Operating Income | B25: =B23*B24 | C25: =C23*C24 | D25: =D23*D24 | E25: =E23*E24 | F25: =F23*F24 | G25: =G23*G24 | H25: =H23*H24 | I25: =I23*I24 | ... M25: =M23*M24
A26: EBIT (1-t) | B26: =B25*(1-B6) | C26: =C25*(1-C6) | D26: =D25*(1-D6) | E26: =E25*(1-E6) | F26: =F25*(1-F6) | G26: =G25*(1-G6) | H26: =H25*(1-H6) | I26: =I25*(1-I6) | ... M26: =M25*(1-M6)
A27: - Reinvestment | C27: =IF('Input sheet'!$B$67="No",(D23-C23)/C57,IF('Input sheet'!$B$68=0,(D23-B23)/C57,IF('Input sheet'!$B$68=2,(E23-D23)/C57,IF('Input sheet'!$B$68=3,(F23-E23)/C57,(D23-C23)/C57)))) | D27: =IF('Input sheet'!$B$67="No",(E23-D23)/D57,IF('Input sheet'!$B$68=0,(E23-C23)/D57,IF('Input sheet'!$B$68=2,(F23-E23)/D57,IF('Input sheet'!$B$68=3,(G23-F23)/D57,(E23-D23)/D57)))) | E27: =IF('Input sheet'!$B$67="No",(F23-E23)/E57,IF('Input sheet'!$B$68=0,(F23-D23)/E57,IF('Input sheet'!$B$68=2,(G23-F23)/E57,IF('Input sheet'!$B$68=3,(H23-G23)/E57,(F23-E23)/E57)))) | F27: =IF('Input sheet'!$B$67="No",(G23-F23)/F57,IF('Input sheet'!$B$68=0,(G23-E23)/F57,IF('Input sheet'!$B$68=2,(H23-G23)/F57,IF('Input sheet'!$B$68=3,(I23-H23)/F57,(G23-F23)/F57)))) | G27: =IF('Input sheet'!$B$67="No",(H23-G23)/G57,IF('Input sheet'!$B$68=0,(H23-F23)/G57,IF('Input sheet'!$B$68=2,(I23-H23)/G57,IF('Input sheet'!$B$68=3,(J23-I23)/G57,(H23-G23)/G57)))) | H27: =IF('Input sheet'!$B$67="No",(I23-H23)/H57,IF('Input sheet'!$B$68=0,(I23-G23)/H57,IF('Input sheet'!$B$68=2,(J23-I23)/H57,IF('Input sheet'!$B$68=3,(K23-J23)/H57,(I23-H23)/H57)))) | I27: =IF('Input sheet'!$B$67="No",(J23-I23)/I57,IF('Input sheet'!$B$68=0,(J23-H23)/I57,IF('Input sheet'!$B$68=2,(K23-J23)/I57,IF('Input sheet'!$B$68=3,(L23-K23)/I57,(J23-I23)/I57)))) | J27: =IF('Input sheet'!$B$67="No",(K23-J23)/J57,IF('Input sheet'!$B$68=0,(K23-I23)/J57,IF('Input sheet'!$B$68=2,(L23-K23)/J57,IF('Input sheet'!$B$68=3,(M23-L23)/J57,(K23-J23)/J57)))) | K27: =IF('Input sheet'!$B$67="No",(L23-K23)/K57,IF('Input sheet'!$B$68=0,(K23-J23)/K57,IF('Input sheet'!$B$68=2,L12*L2/K57,IF('Input sheet'!$B$68=3,M23*M2/K57,(L23-K23)/K57)))) | L27: =IF('Input sheet'!$B$67="No",(M23-L23)/L57,IF('Input sheet'!$B$68=0,(L23-K23)/L57,IF('Input sheet'!$B$68=2,M23*M2/L57,IF('Input sheet'!$B$68=3,(M23*(1+M2)*M2)/L57,(M23-L23)/L57)))) | M27: =IF(M2>0,(M2/M59)*M26,0)
A28: FCFF (AI) | C28: =C26-C27 | D28: =D26-D27 | E28: =E26-E27 | F28: =F26-F27 | G28: =G26-G27 | H28: =H26-H27 | I28: =I26-I27 | J28: =J26-J27 | ... M28: =M26-M27 | N28: =M28/(M30-M2)
A30: Cost of capital | C30: ='Input sheet'!B34 | D30: =C30 | E30: =D30 | F30: =E30 | G30: =F30 | H30: =G30-($G$30-$M$30)/5 | I30: =H30-($G$30-$M$30)/5 | J30: =I30-($G$30-$M$30)/5 | K30: =J30-($G$30-$M$30)/5 | L30: =K30-($G$30-$M$30)/5 | M30: =IF('Input sheet'!B56="Yes",'Input sheet'!B57,IF('Input sheet'!B75="Yes",'Input sheet'!B76+'Country equity risk premiums'!B1,'Input sheet'!B33+'Country equity risk premiums'!B1))
A31: Cumulated discount factor | C31: =1/(1+C30) | D31: =C31*(1/(1+D30)) | E31: =D31*(1/(1+E30)) | F31: =E31*(1/(1+F30)) | G31: =F31*(1/(1+G30)) | H31: =G31*(1/(1+H30)) | I31: =H31*(1/(1+I30)) | J31: =I31*(1/(1+J30)) | K31: =J31*(1/(1+K30)) | L31: =K31*(1/(1+L30))
A32: PV(FCFF from rest) | C32: =C9*C31 | D32: =D9*D31 | E32: =E9*E31 | F32: =F9*F31 | G32: =G9*G31 | H32: =H9*H31 | I32: =I9*I31 | J32: =J9*J31 | ... L32: =L9*L31
A33: PV (FCFF frrom AI) | C33: =C19*C31 | D33: =D19*D31 | E33: =E19*E31 | F33: =F19*F31 | G33: =G19*G31 | H33: =H19*H31 | I33: =I19*I31 | J33: =J19*J31 | ... L33: =L19*L31
A34: PV(FCFF from Auto) | C34: =C28*C31 | D34: =D28*D31 | E34: =E28*E31 | F34: =F28*F31 | G34: =G28*G31 | H34: =H28*H31 | I34: =I28*I31 | J34: =J28*J31 | ... L34: =L28*L31
A37: Value of Rest | B37: =SUM(C32:L32)+N9*L31
A38: Value of AI | B38: =SUM(C33:L33)+N19*L31
A39: Value of Auto | B39: =SUM(C34:L34)+N28*L31
A40: Value as Going Concern = | B40: =SUM(B37:B39)
A41: Probability of failure = | B41: =IF('Input sheet'!B62="Yes",'Input sheet'!B63,0)
A42: Proceeds if firm fails = | B42: =IF('Input sheet'!B64="B",('Input sheet'!B13+'Input sheet'!B14)*'Input sheet'!B65,'Valuation output'!B40*'Input sheet'!B65)
A43: Value of operating assets = | B43: =B40*(1-B41)+B42*B41
A44: - Debt | B44: =IF('Input sheet'!B16="Yes",'Input sheet'!B14+'Operating lease converter'!C28,'Input sheet'!B14)
A45: - Minority interests | B45: ='Input sheet'!B19
...

Sheet Stories to Numbers
A1: ='Input sheet'!B4 | G1: ='Input sheet'!B3
A2: The Opportunistic Chip Maker, after a DeepSeek Disruption
A3: NVIDIA has a history of innovation and opportunism in the chip business, often investing ahead of large trends in demand in crypto and gaming and now in AI and auto. Its early entry into the AI chip business will allow it to dominate this business, but the DeepSeek entry has disrupted the market, creating a two tier market - one commoditized and the other premier; Nvidia will dominate teh latter.. In the auto chip business, NVidia will grow to gain a significant, albeit not dominant, market share as that market grows. Across all of its busineses, NVIDIA will see sustained high operating margins, though the makers of Nvidia chips (especially TSMC) and TSMC's big customers (big tech) will push back, causing margins to drop from 2024 levels. | H3: Tell your story about the company. Keep it focuses on the company's businesses and tie it into the three key levers of value: cash flows, growth and risk
A7: The Assumptions
B8: Base year | C8: Next year | D8: Years 2-5 | E8: Years 6-10 | F8: After year 10 | G8: Link to story
A9: Revenues (a) | B9: ='Valuation output'!B3 | C9: ='Input sheet'!B25 | D9: ='Input sheet'!B27 | F9: ='Valuation output'!M2 | G9: The AI business will be big, but the DeepSeek entry has bifurcated it, into commoditized and premium, and Nvidia will continue to maintain its dominance of the latter. | H9: Tie each assumption to the part of your story that relates to it.
A10: Operating margin (b) | B10: ='Valuation output'!B4 | C10: ='Input sheet'!B26 | F10: ='Valuation output'!M4 | G10: Nvidia will continue to have high margins in its core businesses, and while the AI chip market will be smaller than it was pre-DeepSeek, but some of Nvidia's current competitors may shift to the other AI market.
A11: Tax rate | B11: ='Valuation output'!B6 | D11: =B11 | F11: ='Valuation output'!M6 | G11: Global/US marginal tax rate over time
A12: Reinvestment (c ) | C12: ='Input sheet'!B30 | D12: ='Input sheet'!B30 | E12: ='Input sheet'!B31 | F12: ='Valuation output'!M2/'Valuation output'!M59 | G12: Sales to capital stays higher than industry aveage, as company continues to get growth off past R&D, and focuses research on new AI and auto chips.
A13: Return on capital | B13: ='Valuation output'!B59 | C13: Marginal ROIC = | D13: =Diagnostics!C27 | F13: ='Valuation output'!M59 | G13: Strong competitive edges allow NVIDIA to earn well above its cost of capital for the next decade and beyond.
A14: Cost of capital (d) | D14: ='Valuation output'!C30 | F14: ='Valuation output'!M30 | G14: Initial cost of capital computed based upon industry( (semiconductors) and Nvidia's low debt mix and geographic exposure. Over time, Nvidia's cost of capital will drift down but will remain higher (third quartile) of all companies in market.
A15: The Cash Flows
B16: Revenues | C16: Operating Margin | D16: EBIT | E16: EBIT (1-t) | F16: Reinvestment | G16: FCFF | H16: These are the numbers that come from your assumptions. The revenues over time reflect your revenue growth, the operating margins evolve towards your target margin and your tax rate will change, if you have set it to. The reinvestment is estimated using the sales to capital ratio for the first 10 years and based on a reinvestment rate in stable growth (g/ ROC).
A17: 1 | B17: ='Valuation output'!C3+'Valuation output'!C14+'Valuation output'!C23 | C17: ='Valuation output'!C4 | D17: =B17*C17 | E17: ='Valuation output'!C7 | F17: ='Valuation output'!C8 | G17: =E17-F17
A18: 2 | B18: ='Valuation output'!D3+'Valuation output'!D14+'Valuation output'!D23 | C18: ='Valuation output'!D4 | D18: =B18*C18 | E18: ='Valuation output'!D7 | F18: ='Valuation output'!D8 | G18: =E18-F18
A19: 3 | B19: ='Valuation output'!E3+'Valuation output'!E14+'Valuation output'!E23 | C19: ='Valuation output'!E4 | D19: =B19*C19 | E19: ='Valuation output'!E7 | F19: ='Valuation output'!E8 | G19: =E19-F19
A20: 4 | B20: ='Valuation output'!F3+'Valuation output'!F14+'Valuation output'!F23 | C20: ='Valuation output'!F4 | D20: =B20*C20 | E20: ='Valuation output'!F7 | F20: ='Valuation output'!F8 | G20: =E20-F20
A21: 5 | B21: ='Valuation output'!G3+'Valuation output'!G14+'Valuation output'!G23 | C21: ='Valuation output'!G4 | D21: =B21*C21 | E21: ='Valuation output'!G7 | F21: ='Valuation output'!G8 | G21: =E21-F21
A22: 6 | B22: ='Valuation output'!H3+'Valuation output'!H14+'Valuation output'!H23 | C22: ='Valuation output'!H4 | D22: =B22*C22 | E22: ='Valuation output'!H7 | F22: ='Valuation output'!H8 | G22: =E22-F22
A23: 7 | B23: ='Valuation output'!I3+'Valuation output'!I14+'Valuation output'!I23 | C23: ='Valuation output'!I4 | D23: =B23*C23 | E23: ='Valuation output'!I7 | F23: ='Valuation output'!I8 | G23: =E23-F23
A24: 8 | B24: ='Valuation output'!J3+'Valuation output'!J14+'Valuation output'!J23 | C24: ='Valuation output'!J4 | D24: =B24*C24 | E24: ='Valuation output'!J7 | F24: ='Valuation output'!J8 | G24: =E24-F24
A25: 9 | B25: ='Valuation output'!K3+'Valuation output'!K14+'Valuation output'!K23 | C25: ='Valuation output'!K4 | D25: =B25*C25 | E25: ='Valuation output'!K7 | F25: ='Valuation output'!K8 | G25: =E25-F25
A26: 10 | B26: ='Valuation output'!L3+'Valuation output'!L14+'Valuation output'!L23 | C26: ='Valuation output'!L4 | D26: =B26*C26 | E26: ='Valuation output'!L7 | F26: ='Valuation output'!L8 | G26: =E26-F26
A27: Terminal year | B27: ='Valuation output'!M3+'Valuation output'!M14+'Valuation output'!M23 | C27: ='Valuation output'!M4 | D27: =B27*C27 | E27: ='Valuation output'!M7 | F27: ='Valuation output'!M8 | G27: =E27-F27
A28: The Value
A29: Value of Gaming & Other | D29: ='Valuation output'!B37
A30: Value of AI | D30: ='Valuation output'!B38
A31: Value of Auto | D31: ='Valuation output'!B39
A32: Value of operating assets = | D32: ='Valuation output'!B40
A33: Adjustment for distress | D33: =D32-'Valuation output'!B43 | E33: Probability of failure = | G33: ='Valuation output'!B41
A34: - Debt & Minority Interests | D34: ='Valuation output'!B44+'Valuation output'!B45
A35: + Cash & Other Non-operating assets | D35: ='Valuation output'!B46+'Valuation output'!B47
A36: Value of equity | D36: =D32-D33-D34+D35
A37: - Value of equity options | D37: ='Valuation output'!B49
A38: Number of shares | D38: ='Valuation output'!B51
A39: Value per share | D39: =(D36-D37)/D38 | E39: Stock was trading at = | G39: ='Input sheet'!B21

Sheet Valuation as picture
A1: You can modify this picture and bring in relevant details to back up your cost of capital and other details that you think flesh out your company's valuation story.
A3: ='Input sheet'!B4 | O3: ='Input sheet'!B3
A5: Base Year and Comparison | E5: Growth Story (Revenue) | H5: Profitability Story (Margin) | K5: Growth Efficiency Story
B6: Company | C6: Industry | E6: ='Stories to Numbers'!G9 | H6: ='Stories to Numbers'!G10 | K6: ='Stories to Numbers'!G12 | O6: Terminal Value
A7: Revenue Growth | B7: ='Input sheet'!I25 | C7: ='Input sheet'!K25 | O7: Growth Rate | P7: ='Valuation output'!M2
A8: Revenue | B8: ='Valuation output'!B3+'Valuation output'!B14+'Valuation output'!B23 | O8: Cost of capital | P8: ='Valuation output'!M30
A9: Operating Margin | B9: =B10/B8 | C9: ='Input sheet'!K26 | O9: Return on capital | P9: ='Valuation output'!M59
A10: Operating Income | B10: ='Valuation output'!B5+'Valuation output'!B16+'Valuation output'!B25 | O10: Reinvestment Rate | P10: =P7/P9
A11: EBIT (1-t) | B11: ='Valuation output'!B7
A15: ='Valuation output'!A37 | B15: ='Valuation output'!B37 | E15: ='Valuation output'!C1 | F15: ='Valuation output'!D1 | G15: ='Valuation output'!E1 | H15: ='Valuation output'!F1 | I15: ='Valuation output'!G1 | J15: ='Valuation output'!H1 | K15: ='Valuation output'!I1 | L15: ='Valuation output'!J1 | ... O15: ='Valuation output'!M1
A16: ='Valuation output'!A38 | B16: ='Valuation output'!B38 | D16: Revenue (Gaming/Other) | E16: ='Valuation output'!C3 | F16: ='Valuation output'!D3 | G16: ='Valuation output'!E3 | H16: ='Valuation output'!F3 | I16: ='Valuation output'!G3 | J16: ='Valuation output'!H3 | K16: ='Valuation output'!I3 | L16: ='Valuation output'!J3 | ... O16: ='Valuation output'!M3
A17: ='Valuation output'!A39 | B17: ='Valuation output'!B39 | D17: Revenue (AI) | E17: ='Valuation output'!C14 | F17: ='Valuation output'!D14 | G17: ='Valuation output'!E14 | H17: ='Valuation output'!F14 | I17: ='Valuation output'!G14 | J17: ='Valuation output'!H14 | K17: ='Valuation output'!I14 | L17: ='Valuation output'!J14 | ... O17: ='Valuation output'!M14
A18: ='Valuation output'!A41 | B18: ='Valuation output'!B41 | D18: Revenue (Auto) | E18: ='Valuation output'!C23 | F18: ='Valuation output'!D23 | G18: ='Valuation output'!E23 | H18: ='Valuation output'!F23 | I18: ='Valuation output'!G23 | J18: ='Valuation output'!H23 | K18: ='Valuation output'!I23 | L18: ='Valuation output'!J23 | ... O18: ='Valuation output'!M23
A19: ='Valuation output'!A43 | B19: ='Valuation output'!B43 | D19: Revenues (Total) | E19: =E16+E17+E18 | F19: =F16+F17+F18 | G19: =G16+G17+G18 | H19: =H16+H17+H18 | I19: =I16+I17+I18 | J19: =J16+J17+J18 | K19: =K16+K17+K18 | L19: =L16+L17+L18 | ... O19: =O16+O17+O18
A20: ='Valuation output'!A44 | B20: ='Valuation output'!B44 | D20: R&D Adj Operating Margin | E20: ='Valuation output'!C4 | F20: ='Valuation output'!D4 | G20: ='Valuation output'!E4 | H20: ='Valuation output'!F4 | I20: ='Valuation output'!G4 | J20: ='Valuation output'!H4 | K20: ='Valuation output'!I4 | L20: ='Valuation output'!J4 | ... O20: ='Valuation output'!M4
A21: ='Valuation output'!A45 | B21: ='Valuation output'!B45 | D21: Operating Income | E21: ='Valuation output'!C5+'Valuation output'!C16+'Valuation output'!C25 | F21: ='Valuation output'!D5+'Valuation output'!D16+'Valuation output'!D25 | G21: ='Valuation output'!E5+'Valuation output'!E16+'Valuation output'!E25 | H21: ='Valuation output'!F5+'Valuation output'!F16+'Valuation output'!F25 | I21: ='Valuation output'!G5+'Valuation output'!G16+'Valuation output'!G25 | J21: ='Valuation output'!H5+'Valuation output'!H16+'Valuation output'!H25 | K21: ='Valuation output'!I5+'Valuation output'!I16+'Valuation output'!I25 | L21: ='Valuation output'!J5+'Valuation output'!J16+'Valuation output'!J25 | ... O21: ='Valuation output'!M5+'Valuation output'!M16+'Valuation output'!M25
A22: ='Valuation output'!A46 | B22: ='Valuation output'!B46 | D22: EBIT (1-t) | E22: ='Valuation output'!C7+'Valuation output'!C17+'Valuation output'!C26 | F22: ='Valuation output'!D7+'Valuation output'!D17+'Valuation output'!D26 | G22: ='Valuation output'!E7+'Valuation output'!E17+'Valuation output'!E26 | H22: ='Valuation output'!F7+'Valuation output'!F17+'Valuation output'!F26 | I22: ='Valuation output'!G7+'Valuation output'!G17+'Valuation output'!G26 | J22: ='Valuation output'!H7+'Valuation output'!H17+'Valuation output'!H26 | K22: ='Valuation output'!I7+'Valuation output'!I17+'Valuation output'!I26 | L22: ='Valuation output'!J7+'Valuation output'!J17+'Valuation output'!J26 | ... O22: ='Valuation output'!M7+'Valuation output'!M17+'Valuation output'!M26
A23: ='Valuation output'!A47 | B23: ='Valuation output'!B47 | D23: Reinvestment | E23: ='Valuation output'!C8+'Valuation output'!C18+'Valuation output'!C27 | F23: ='Valuation output'!D8+'Valuation output'!D18+'Valuation output'!D27 | G23: ='Valuation output'!E8+'Valuation output'!E18+'Valuation output'!E27 | H23: ='Valuation output'!F8+'Valuation output'!F18+'Valuation output'!F27 | I23: ='Valuation output'!G8+'Valuation output'!G18+'Valuation output'!G27 | J23: ='Valuation output'!H8+'Valuation output'!H18+'Valuation output'!H27 | K23: ='Valuation output'!I8+'Valuation output'!I18+'Valuation output'!I27 | L23: ='Valuation output'!J8+'Valuation output'!J18+'Valuation output'!J27 | ... O23: ='Valuation output'!M8+'Valuation output'!M18+'Valuation output'!M27
A24: ='Valuation output'!A48 | B24: ='Valuation output'!B48 | D24: FCFF | E24: ='Valuation output'!C9+'Valuation output'!C19+'Valuation output'!C28 | F24: ='Valuation output'!D9+'Valuation output'!D19+'Valuation output'!D28 | G24: ='Valuation output'!E9+'Valuation output'!E19+'Valuation output'!E28 | H24: ='Valuation output'!F9+'Valuation output'!F19+'Valuation output'!F28 | I24: ='Valuation output'!G9+'Valuation output'!G19+'Valuation output'!G28 | J24: ='Valuation output'!H9+'Valuation output'!H19+'Valuation output'!H28 | K24: ='Valuation output'!I9+'Valuation output'!I19+'Valuation output'!I28 | L24: ='Valuation output'!J9+'Valuation output'!J19+'Valuation output'!J28 | ... O24: ='Valuation output'!M9+'Valuation output'!M19+'Valuation output'!M28
A25: ='Valuation output'!A49 | B25: ='Valuation output'!B49 | N25: ='Valuation output'!N9+'Valuation output'!N19+'Valuation output'!N28
A26: ='Valuation output'!A50 | B26: ='Valuation output'!B50
A27: ='Valuation output'!A51 | B27: ='Valuation output'!B51 | D27: Cost of Capital | E27: ='Valuation output'!C30 | F27: ='Valuation output'!D30 | G27: ='Valuation output'!E30 | H27: ='Valuation output'!F30 | I27: ='Valuation output'!G30 | J27: ='Valuation output'!H30 | K27: ='Valuation output'!I30 | L27: ='Valuation output'!J30 | ... N27: ='Valuation output'!L30
A28: ='Valuation output'!A52 | B28: ='Valuation output'!B52 | D28: Cumulated WACC | E28: ='Valuation output'!C31 | F28: ='Valuation output'!D31 | G28: ='Valuation output'!E31 | H28: ='Valuation output'!F31 | I28: ='Valuation output'!G31 | J28: ='Valuation output'!H31 | K28: ='Valuation output'!I31 | L28: ='Valuation output'!J31 | ... N28: ='Valuation output'!L31
A30: Price per share | B30: ='Stories to Numbers'!G39 | D30: Sales to Capital | E30: ='Valuation output'!C57 | F30: ='Valuation output'!D57 | G30: ='Valuation output'!E57 | H30: ='Valuation output'!F57 | I30: ='Valuation output'!G57 | J30: ='Valuation output'!H57 | K30: ='Valuation output'!I57 | L30: ='Valuation output'!J57 | ... N30: ='Valuation output'!L57
A31: % Under or Over Valued | B31: =B30/B28-1 | D31: ROIC | E31: ='Valuation output'!C59 | F31: ='Valuation output'!D59 | G31: ='Valuation output'!E59 | H31: ='Valuation output'!F59 | I31: ='Valuation output'!G59 | J31: ='Valuation output'!H59 | K31: ='Valuation output'!I59 | L31: ='Valuation output'!J59 | ... O31: ='Valuation output'!M59
D34: Risk Story | G34: Competitive Advantages | L34: AI and Auto Business: Market Size and Market Share
D35: ='Stories to Numbers'!G14 | G35: ='Stories to Numbers'!G13 | M35: AI | O35: Auto
M36: Current | N36: In 2034 | O36: Current | P36: In 2034
L37: Total Market ($ M) | M37: ='Input sheet'!B44 | N37: ='Input sheet'!C44 | O37: ='Input sheet'!B50 | P37: ='Input sheet'!C50
L38: Market Share | M38: ='Input sheet'!B45 | N38: ='Input sheet'!C45 | O38: ='Input sheet'!B51 | P38: ='Input sheet'!C51
L39: NVIDIA revenues | M39: =M37*M38 | N39: =N37*N38 | O39: =O37*O38 | P39: =P37*P38

Sheet Diagnostics
A1: Step 1: Check revenue growth rate | D1: Your forecasts | G1: Questions to ask
B2: Industry Average | C2: Most Recent year | D2: Next year | E2: Years 2-5 | G2: 1. If you are forecasting a revenue growth rate > industry average, is your company small?
A3: Annual Revenue Growth Rate | B3: ='Input sheet'!J25 | C3: ='Input sheet'!I25 | D3: =C7/B7-1 | E3: =(D7/B7)^(1/5)-1 | G3: 2. If your forecasted revenue growth rate is very different from your company's most recent year of growth, what is the reason?
A5: Step 2: Check dollar revenues
B6: Most Recent year | C6: Next year | D6: Year 5 | E6: Year 10 | G6: 1. How big is the total market today?
A7: Revenues | B7: ='Valuation output'!B3+'Valuation output'!B14+'Valuation output'!B23 | C7: ='Valuation output'!C3+'Valuation output'!C14+'Valuation output'!C23 | D7: ='Valuation output'!G3+'Valuation output'!G14+'Valuation output'!G23 | E7: ='Valuation output'!L3+'Valuation output'!L14+'Valuation output'!L23 | G7: 2. How much revenues do the biggest companies in that market make today?
G8: 3. How much growth is there in the total market?
G9: 4. What type of market share are you forecasting for your company in year 10?
A11: Step 3: Check your margins | B11: Most Recent year | C11: Next year | D11: Year 5 | E11: Year 10 | G11: 1. What are the margins of the industry that the company is in?
A12: Operating Margin | B12: ='Valuation output'!B4 | C12: ='Valuation output'!C4 | D12: ='Valuation output'!G4 | E12: ='Valuation output'!M4 | G12: 2. What are the unit economics of the business? (How much does it cost you to make the extra unit that you sell?
G13: 3. What does the competition in this business look like?
A15: Step 4: Check how much you are reinvesting
B16: Most Recent year | C16: Next year | D16: Year 5 | E16: Year 10 | G16: 1. is the growth that you are forecasting bounce-back growth or new growth?
A17: Sales to Capital | B17: ='Input sheet'!I27 | C17: ='Valuation output'!C57 | D17: ='Valuation output'!G57 | E17: ='Valuation output'!L57 | G17: 2. How much excess capacity do you have to service near term growth?
G18: 3. Does investment efficiency in this business change as companies get bigger?
A19: Reinvestment effect on cash flows
B20: $ Value | C20: As % of value
A21: PV of after-tax operating income for next 10 years | B21: =('Valuation output'!C7+'Valuation output'!C17+'Valuation output'!C26)*'Valuation output'!C31+('Valuation output'!D7+'Valuation output'!D17+'Valuation output'!D26)*'Valuation output'!D31+('Valuation output'!E7+'Valuation output'!E17+'Valuation output'!E26)*'Valuation output'!E31+('Valuation output'!F7+'Valuation output'!F17+'Valuation output'!F26)*'Valuation output'!F31+('Valuation output'!G7+'Valuation output'!G17+'Valuation output'!G26)*'Valuation output'!G31+('Valuation output'!H7+'Valuation output'!H17+'Valuation output'!H26)*'Valuation output'!H31+('Valuation output'!I7+'Valuation output'!I17+'Valuation output'!I26)*'Valuation output'!I31+('Valuation output'!J7+'Valuation output'!J17+'Valuation output'!J26)*'Valuation output'!J31+('Valuation output'!K7+'Valuation output'!K17+'Valuation output'!K26)*'Valuation output'!K31+('Valuation output'!L7+'Valuation output'!L17+'Valuation output'!L26)*'Valuation output'!C31+('Valuation output'!M7+'Valuation output'!M17+'Valuation output'!M26)*'Valuation output'!M31 | C21: =B21/B21 | G21: 1. Is your reinvestment consitent with your revenue growth forecast?
A22: Value effect of reinvestment for next 10 years | B22: =B21-B23 | C22: =B22/B21 | G22: 2. Are you comfortable with your return on capital in year 10?
A23: PV of FCFF for next ten years | B23: =SUM('Valuation output'!C32:L32)+SUM('Valuation output'!C33:L33)+SUM('Valuation output'!C34:L34) | C23: =C21-C22
A25: Return on capital effects
B26: Most recent year | C26: Marginal (1-10) | D26: ROC in year 10 | E26: Stable ROC
A27: Return on capital | B27: ='Valuation output'!B59 | C27: =('Valuation output'!L7-'Valuation output'!B7+'Valuation output'!L17-'Valuation output'!B17+'Valuation output'!L26-'Valuation output'!B26-'Valuation output'!B26)/('Valuation output'!L58-'Valuation output'!B58) | D27: ='Valuation output'!L59 | E27: ='Valuation output'!M59
A29: Step 5: Risk Metrics
B30: Industry Average | C30: Compounded | D30: Year 1-5 | E30: Stable Growth | G30: 1. How does your cost of capital compare to the industry average?
A31: Cost of capital | B31: ='Input sheet'!J31 | C31: =(1/'Valuation output'!L31)^(1/10)-1 | D31: ='Valuation output'!C30 | E31: ='Valuation output'!M30 | G31: 2. What is happenign to your cost of capital over time? Why?
G32: 3. Is your failure rate consistent with your company's characteristics?
A33: Failure Rate | B33: ='Valuation output'!B41
A35: Step 6: Price versus Value
A36: Your calculated value as a percent of current price | B36: ='Valuation output'!B52/'Valuation output'!B53
B37: =IF(B36="NA","Value is negative. See below",IF(B36>2,"Value seems high. See below",IF(B36<0.5,"Value seems low. See below"," ")))
A38: Inputs | B38: If calculated value is negative or looks too low | C38: If calculated value looks too high
A39: Revenue growth rate (input cell B25, B27) | B39: Increase revenue growth rate | C39: Decrease revenue growth rate
A40: Operating margin (B26, B28) | B40: Increase the target pre-tax operating margin | C40: Decrease the target pre-tax operating margin
A41: Sales to Capital (B30-B32) | B41: Increase the sales/capital ratio | C41: Decrease the sales/capital ratio
A42: Return on capital in perpetuity (B48, B49) | B42: Increase relative to your cost of capital | C42: If higher than your cost of capital, lower towards your cost of capital

Sheet Option value
A1: Note: This worksheet is the most finicky of all of the worksheets in this spreadsheet. If you start to get errors, here is a quick fix. Go into cell B12 and replace the contents with a number (say 5), and then undo your action. The spreadsheet will fix itself magically.
A3: Valuing Options or Warrants
A4: Enter the current stock price = | B4: ='Input sheet'!B21
A5: Enter the strike price on the option = | B5: ='Input sheet'!B38
A6: Enter the expiration of the option = | B6: ='Input sheet'!B39
A7: Enter the standard deviation in stock prices = | B7: ='Input sheet'!B40 | C7: (volatility)
A8: Enter the annualized dividend yield on stock = | B8: 0
A9: Enter the treasury bond rate = | B9: ='Input sheet'!B33
A10: Enter the number of warrants (options) outstanding = | B10: ='Input sheet'!B37
A11: Enter the number of shares outstanding = | B11: ='Input sheet'!B20
A13: Do not input any numbers below this line
A14: Dilution-adjusted Black-Scholes
A15: Stock Price= | B15: =B4 | C15: # Warrants issued= | D15: =B10
A16: Strike Price= | B16: =B5 | C16: # Shares outstanding= | D16: =B11
A17: Adjusted S = | B17: =(B15*D16+B28*D15)/(D16+D15) | C17: T.Bond rate= | D17: =B9
A18: Adjusted K = | B18: =B16 | C18: Variance= | D18: =B7^2
A19: Expiration (in years) = | B19: =B6 | C19: Annualized dividend yield= | D19: =B8
C20: Div. Adj. interest rate= | D20: =D17-D19
A22: d1 = | B22: =(LN(B17/B18)+(D20+(D18/2))*B19)/(((D18)^(0.5))*(B19^0.5))
A23: N (d1) = | B23: =NORMSDIST(B22)
A25: d2 = | B25: =B22-((D18^0.5)*(B19^(0.5)))
A26: N (d2) = | B26: =NORMSDIST(B25)
A28: Value per option = | B28: =((EXP((0-D19)*B19))*B17*B23-B18*(EXP((0-D17)*B19))*B26)
A29: Value of all options outstanding = | B29: =B28*B10

Sheet Operating lease converter
A1: Operating Lease Converter
A2: The yellow cells are input cells. Please enter them.
A3: Inputs | H3: Until 2019, this worksheet had to be used for every firm with operating lease commitments, since accountants treated operating lease expenses as operating expenses. In 2019, IFRS and GAAP made the long-overdue change to treat leases as debt, and for firms that follow these standards, the conversion that I am doing on this spreadsheet is being done by accountants, with lease debt and operating income already adjusted. If that is the case, and you showed the lease debt as part of debt in the input page, please do not use this spreadsheet, since you will be double counting.
A4: Operating lease expense in current year = | E4: 295
A5: Operating Lease Commitments (From footnote to financials)
A6: Year | B6: Commitment | C6: ! Year 1 is next year, ….
A7: 1 | B7: 287
A8: 2 | B8: 235
A9: 3 | B9: 194
A10: 4 | B10: 151
A11: 5 | B11: 98
A12: 6 and beyond | B12: 605
A14: Output
A15: Pre-tax Cost of Debt = | C15: ='Cost of capital worksheet'!B37 | D15: ! If you do not have a cost of debt, use the synthetic rating estimator
A18: Number of years embedded in yr 6 estimate = | D18: =IF(B12>0,ROUND(B12/AVERAGE(B7:B11),0),0) | E18: ! I use the average lease expense over the first five years
E19: to estimate the number of years of expenses in yr 6
A20: Converting Operating Leases into debt
A21: Year | B21: Commitment | C21: Present Value
A22: =A7 | B22: =B7 | C22: =B22/(1+$C$15)^A22
A23: =A8 | B23: =B8 | C23: =B23/(1+$C$15)^A23
A24: =A9 | B24: =B9 | C24: =B24/(1+$C$15)^A24
A25: =A10 | B25: =B10 | C25: =B25/(1+$C$15)^A25
A26: =A11 | B26: =B11 | C26: =B26/(1+$C$15)^A26
A27: =A12 | B27: =IF(B12>0,IF(D18>0,B12/D18,B12),0) | C27: =IF(D18>0,(B27*(1-(1+C15)^(-D18))/C15)/(1+$C$15)^5,B27/(1+C15)^6) | D27: ! Commitment beyond year 6 converted into an annuity for ten years
A28: Debt Value of leases = | C28: =SUM(C22:C27)
A30: Restated Financials
A31: Depreciation on Operating Lease Asset = | F31: =C28/(5+D18) | G31: ! I use straight line depreciation
A32: Adjustment to Operating Earnings = | F32: =E4-F31 | G32: ! Add this amount to pre-tax operating income
A33: Adjustment to Total Debt outstanding = | F33: =C28 | G33: ! Add this amount to debt
A34: Adjustment to Depreciation = | F34: =C28/(5+D18)

Sheet Synthetic rating
A1: If you have negative operating income, this spreadsheet will offer you a D rating. Do not use that rating as your cost of debt for a going concern. Insread give your company a low, but going concern rating like BB and use that cost of debt.
A4: Inputs for synthetic rating estimation
A5: Please read the special cases worksheet (see below) before you use this spreadsheet.
A6: Before you use this spreadsheet, make sure that the iteration box (under calculation options in excel) is checked.
A7: Enter the type of firm = | C7: ='Cost of capital worksheet'!B36
A8: Enter current Earnings before interest and taxes (EBIT) = | F8: =IF('Input sheet'!B16="Yes",'Input sheet'!B11+'Operating lease converter'!F32,'Input sheet'!B11) | G8: (Add back only long term interest expense for financial firms)
A9: Enter current interest expenses = | F9: =IF('Input sheet'!B16="Yes",'Cost of capital worksheet'!B31+'Operating lease converter'!C28*'Operating lease converter'!C15,'Cost of capital worksheet'!B31) | G9: (Use only long term interest expense for financial firms)
A10: Enter long term risk free rate = | F10: ='Input sheet'!B33
A11: Output
A12: Interest coverage ratio = | D12: =IF(F9=0,1000000,IF(F8<0,-100000,F8/F9))
A13: Estimated Bond Rating = | D13: =IF(C7=1,VLOOKUP(D12,A22:D36,3),(IF(C7=2,VLOOKUP(D12,A41:D55,3),VLOOKUP(D12,F22:I36,3)))) | F13: Note: If you get REF! All over the place, set the operating lease commitment question in cell F5
A14: Estimated Company Default Spread = | D14: =IF(C7=1,VLOOKUP(D12,A22:D36,4),(IF(C7=2,VLOOKUP(D12,A41:D55,4),VLOOKUP(D12,F22:I36,4)))) | F14: to No, and then reset it to Yes. It should work.
A15: Estimated County Default Spread (if any) = | D15: =VLOOKUP('Input sheet'!B7,'Country equity risk premiums'!A5:C196,3)
A16: Estimated Cost of Debt = | D16: =F10+D14+D15
A18: If you want to update the spreads listed below, please visit http://www.bondsonline.com
A19: For large manufacturing firms | J19: Default Probabilities over time (1 - 10 year time horizons)
A20: If interest coverage ratio is | J20: Rating | K20: 1 | L20: 2 | M20: 3 | N20: 4 | O20: 5 | P20: 6 | Q20: 7 | R20: 8 | S20: 9 | T20: 10
A21: > | B21: ≤ to | C21: Rating is | D21: Spread is | J21: AAA | K21: 0 | L21: 0.0003 | M21: 0.0013 | N21: 0.0024 | O21: 0.0035 | P21: 0.0045 | Q21: 0.0051 | R21: 0.0059 | S21: 0.0064 | T21: 0.007
A22: -100000 | B22: 0.199999 | C22: D2/D | D22: 0.2 | J22: AA | K22: 0.0002 | L22: 0.0006 | M22: 0.0012 | N22: 0.0021 | O22: 0.0031 | P22: 0.0042 | Q22: 0.005 | R22: 0.0058 | S22: 0.0065 | T22: 0.0072
A23: 0.2 | B23: 0.649999 | C23: C2/C | D23: 0.175 | J23: A | K23: 0.0005 | L23: 0.0014 | M23: 0.0023 | N23: 0.0035 | O23: 0.0047 | P23: 0.0062 | Q23: 0.0079 | R23: 0.0093 | S23: 0.0108 | T23: 0.0124
A24: 0.65 | B24: 0.799999 | C24: Ca2/CC | D24: 0.1578 | J24: BBB | K24: 0.0016 | L24: 0.0045 | M24: 0.0078 | N24: 0.0117 | O24: 0.0158 | P24: 0.0198 | Q24: 0.0233 | R24: 0.0267 | S24: 0.03 | T24: 0.0332
A25: 0.8 | B25: 1.249999 | C25: Caa/CCC | D25: 0.1157 | J25: BB | K25: 0.0061 | L25: 0.0192 | M25: 0.0348 | N25: 0.0505 | O25: 0.0652 | P25: 0.0785 | Q25: 0.0901 | R25: 0.1004 | S25: 0.1097 | T25: 0.1178
A26: 1.25 | B26: 1.499999 | C26: B3/B- | D26: 0.0737 | J26: B | K26: 0.0333 | L26: 0.0771 | M26: 0.1155 | N26: 0.1458 | O26: 0.1693 | P26: 0.1883 | Q26: 0.2036 | R26: 0.216 | S26: 0.227 | T26: 0.2374
A27: 1.5 | B27: 1.749999 | C27: B2/B | D27: 0.0526 | J27: CCC/C | K27: 0.2708 | L27: 0.3664 | M27: 0.4141 | N27: 0.441 | O27: 0.4619 | P27: 0.4709 | Q27: 0.4826 | R27: 0.4905 | S27: 0.4976 | T27: 0.5038
A28: 1.75 | B28: 1.999999 | C28: B1/B+ | D28: 0.0455
A29: 2 | B29: 2.2499999 | C29: Ba2/BB | D29: 0.0313
A30: 2.25 | B30: 2.49999 | C30: Ba1/BB+ | D30: 0.0242
A31: 2.5 | B31: 2.999999 | C31: Baa2/BBB | D31: 0.02
A32: 3 | B32: 4.249999 | C32: A3/A- | D32: 0.0162
A33: 4.25 | B33: 5.499999 | C33: A2/A | D33: 0.0142
A34: 5.5 | B34: 6.499999 | C34: A1/A+ | D34: 0.0123
A35: 6.5 | B35: 8.499999 | C35: Aa2/AA | D35: 0.0085
A36: 8.5 | B36: 100000 | C36: Aaa/AAA | D36: 0.0069
A38: For smaller and riskier firms
A39: If interest coverage ratio is
A40: greater than | B40: ≤ to | C40: Rating is | D40: Spread is
A41: -100000 | B41: 0.499999 | C41: D2/D | D41: 0.2 | G41: Rating is | H41: Spread is
A42: 0.5 | B42: 0.799999 | C42: C2/C | D42: 0.175 | G42: A1/A+ | H42: 0.0123
A43: 0.8 | B43: 1.249999 | C43: Ca2/CC | D43: 0.1578 | G43: A2/A | H43: 0.0142
A44: 1.25 | B44: 1.499999 | C44: Caa/CCC | D44: 0.1157 | G44: A3/A- | H44: 0.0162
...

Sheet R& D converter
A1: R & D Converter
A2: This spreadsheet converts R&D expenses from operating to capital expenses. It makes the appropriate adjustments to operating income, net
A3: income, the book value of assets and the book value of equity.
A5: Inputs
A6: Over how many years do you want to amortize R&D expenses | B6: 5 | F6: 5 | G6: ! If in doubt, use the lookup table below
A7: Enter the current year's R&D expense = | B7: 2288.204 | F7: 11665 | G7: The maximum allowed is ten years
A8: Enter R& D expenses for past years: the number of years that you will need to enter will be determined by the amortization period
A9: Do not input numbers in the first column (Year). It will get automatically updated based on the input above.
A10: Year | B10: R& D Expenses
A11: -1 | B11: 2027.532 | C11: ! Year -1 is the year prior to the current year
A12: =IF((0-A11)<$F$6,IF(A11>-1,,A11-1),) | B12: 2195.329 | C12: ! Year -2 is the two years prior to the current year
A13: =IF((0-A12)<$F$6,IF(A12>-1,,A12-1),) | B13: 2073.461
A14: =IF((0-A13)<$F$6,IF(A13>-1,,A13-1),) | B14: 1453.912
A15: =IF((0-A14)<$F$6,IF(A14>-1,,A14-1),) | B15: 1335.744
A16: =IF((0-A15)<$F$6,IF(A15>-1,,A15-1),) | B16: 1266.341
A17: =IF((0-A16)<$F$6,IF(A16>-1,,A16-1),) | B17: 1273.729
A18: =IF((0-A17)<$F$6,IF(A17>-1,,A17-1),) | B18: 1361.691
A19: =IF((0-A18)<$F$6,IF(A18>-1,,A18-1),) | B19: 1491.37
A20: =IF((0-A19)<$F$6,IF(A19>-1,,A19-1),) | B20: 1220.919
A22: Output
A23: Year | B23: R&D Expense | C23: Unamortized portion | E23: Amortization this year
A24: Current | B24: =F7 | C24: =1 | D24: =B24*C24
A25: =A11 | B25: =B11 | C25: =IF(A25<0,($F$6+A25)/$F$6,0) | D25: =B25*C25 | E25: =IF(A25<0,B25/$F$6,0)
A26: =A12 | B26: =B12 | C26: =IF(A26<0,($F$6+A26)/$F$6,0) | D26: =B26*C26 | E26: =IF(A26<0,B26/$F$6,0)
A27: =A13 | B27: =B13 | C27: =IF(A27<0,($F$6+A27)/$F$6,0) | D27: =B27*C27 | E27: =IF(A27<0,B27/$F$6,0)
A28: =A14 | B28: =B14 | C28: =IF(A28<0,($F$6+A28)/$F$6,0) | D28: =B28*C28 | E28: =IF(A28<0,B28/$F$6,0)
A29: =A15 | B29: =B15 | C29: =IF(A29<0,($F$6+A29)/$F$6,0) | D29: =B29*C29 | E29: =IF(A29<0,B29/$F$6,0)
A30: =A16 | B30: =B16 | C30: =IF(A30<0,($F$6+A30)/$F$6,0) | D30: =B30*C30 | E30: =IF(A30<0,B30/$F$6,0)
A31: =A17 | B31: =B17 | C31: =IF(A31<0,($F$6+A31)/$F$6,0) | D31: =B31*C31 | E31: =IF(A31<0,B31/$F$6,0)
A32: =A18 | B32: =B18 | C32: =IF(A32<0,($F$6+A32)/$F$6,0) | D32: =B32*C32 | E32: =IF(A32<0,B32/$F$6,0)
A33: =A19 | B33: =B19 | C33: =IF(A33<0,($F$6+A33)/$F$6,0) | D33: =B33*C33 | E33: =IF(A33<0,B33/$F$6,0)
A34: =A20 | B34: =B20 | C34: =IF(A34<0,($F$6+A34)/$F$6,0) | D34: =B34*C34 | E34: =IF(A34<0,B34/$F$6,0)
A35: Value of Research Asset = | D35: =SUM(D24:D34) | E35: =SUM(E25:E34)
A37: Amortization of asset for current year = | D37: =E35
A39: Adjustment to Operating Income = | D39: =F7-D37 | E39: ! A positive number indicates an increase in operating income (add to reported EBIT)
A40: Tax Effect of R&D Expensing | D40: =D39*'Input sheet'!B23

Sheet Cost of capital worksheet
A1: You can use this spreadsheet to compute your cost of capital. You can either use the built-in data to compute key inputs (beta, equity risk premium, default spread) or enter them directly. If you choose to use the built in ERP data, you can update the ERP numbers to reflect a more current mature market premuum (since the spreadsheet uses the start of the year numbers).
A3: Estimation of Current Cost of Capital | G3: Operating Countries ERP calculator
A4: There are four ways in whch you can estimate your cost of capital. In the first, you can directly input a cost of captial. In the second, you can work through your company's cost of capital inputs in detail, entering business, geogaphical mix and debt, and I will help you estimate a cost of capital. In the third, you can look up the cost of capital for the industry your firm belongs to and in the fourth, you can use a crosssectoinal distribution of costs of capital for companies at the start of the year to make your estimate. | G4: Country | H4: Revenues | I4: ERP | J4: Weight | K4: Weighted ERP
G5: United States | H5: 26966 | I5: =IF(H5=0,0,VLOOKUP(G5,'Country equity risk premiums'!$A$5:$D$196,4)) | J5: =IF(H5>0,H5/$H$18,) | K5: =IF(J5=0,0,I5*J5) | M5: The last two rows in each of country/region risk premium tables is set aside for your input to provide you with flexibility to enter some numbers directly. For instance, assume that you have a company that breaks its revenues down into three countries and then puts the rest into "Rest of the World". You can enter the "Rest of the World" in one of these two rows and enter an equity risk premium for the rest of the world. The easiest way to do that is to go into the country equity risk premium worksheet and change the GDP for the three countries that you have data for to zero and compute the global weighted average ERP for the remaining countries. With the regional worksheet, you can use the last two rows to enter the data for an individual country (usually the domestic country) that might be broken out though the rest of the revenues are broken down by region. You can look up the ERP for the country in the country ERP worksheet. | S5: United States | T5: 26966
G6: China | H6: 10306 | I6: =IF(H6=0,0,VLOOKUP(G6,'Country equity risk premiums'!$A$5:$D$196,4)) | J6: =IF(H6>0,H6/$H$18,) | K6: =IF(J6=0,0,I6*J6) | S6: Taiwan | T6: 13405
G7: Taiwan | H7: 13405 | I7: =IF(H7=0,0,VLOOKUP(G7,'Country equity risk premiums'!$A$5:$D$196,4)) | J7: =IF(H7>0,H7/$H$18,) | K7: =IF(J7=0,0,I7*J7) | S7: China (Including Hong Kong) | T7: 10306
I8: =IF(H8=0,0,VLOOKUP(G8,'Country equity risk premiums'!$A$5:$D$196,4)) | J8: =IF(H8>0,H8/$H$18,) | K8: =IF(J8=0,0,I8*J8) | S8: Other Countries | T8: 10245
I9: =IF(H9=0,0,VLOOKUP(G9,'Country equity risk premiums'!$A$5:$D$196,4)) | J9: =IF(H9>0,H9/$H$18,) | K9: =IF(J9=0,0,I9*J9)
I10: =IF(H10=0,0,VLOOKUP(G10,'Country equity risk premiums'!$A$5:$D$196,4)) | J10: =IF(H10>0,H10/$H$18,) | K10: =IF(J10=0,0,I10*J10)
A11: Which approach will you be using? | B11: Detailed | I11: =IF(H11=0,0,VLOOKUP(G11,'Country equity risk premiums'!$A$5:$D$196,4)) | J11: =IF(H11>0,H11/$H$18,) | K11: =IF(J11=0,0,I11*J11)
A12: If direct input, enter cost of capital to use | B12: 0.09 | I12: =IF(H12=0,0,VLOOKUP(G12,'Country equity risk premiums'!$A$5:$D$196,4)) | J12: =IF(H12>0,H12/$H$18,) | K12: =IF(J12=0,0,I12*J12)
A13: Cost of capital based upon approach = | B13: =IF(B11="I will input",B12,IF(B11="Detailed",E62,IF(B11="Industry Average",B67,B72))) | I13: =IF(H13=0,0,VLOOKUP(G13,'Country equity risk premiums'!$A$5:$D$196,4)) | J13: =IF(H13>0,H13/$H$18,) | K13: =IF(J13=0,0,I13*J13)
I14: =IF(H14=0,0,VLOOKUP(G14,'Country equity risk premiums'!$A$5:$D$196,4)) | J14: =IF(H14>0,H14/$H$18,) | K14: =IF(J14=0,0,I14*J14)
A15: Approach 1: Detailed Cost of Capital | I15: =IF(H15=0,0,VLOOKUP(G15,'Country equity risk premiums'!$A$5:$D$196,4)) | J15: =IF(H15>0,H15/$H$18,) | K15: =IF(J15=0,0,I15*J15)
A16: Inputs | G16: Rest of the World | H16: 10245 | I16: 0.055 | J16: =IF(H16>0,H16/$H$18,) | K16: =IF(J16=0,0,I16*J16)
A17: Equity | J17: =IF(H17>0,H17/$H$18,) | K17: =IF(J17=0,0,I17*J17)
A18: Number of Shares outstanding = | B18: ='Input sheet'!B20 | G18: Total | H18: =SUM(H5:H17) | J18: =SUM(J5:J17) | K18: =SUM(K5:K17)
A19: Current Market Price per share = | B19: ='Input sheet'!B21 | G19: Operating Regions ERP calculator
G20: Region | H20: Revenues | I20: ERP | J20: Weight | K20: Weighted ERP
A21: Approach for estimating beta | B21: Single Business(US) | G21: ='Country equity risk premiums'!A201 | I21: ='Country equity risk premiums'!B201 | J21: =H21/$H$32 | K21: =I21*J21
A22: If direct input, enter levered beta (or regression beta) | B22: 1.2 | G22: ='Country equity risk premiums'!A202 | H22: 27899 | I22: ='Country equity risk premiums'!B202 | J22: =H22/$H$32 | K22: =I22*J22
